<?xml version="1.0" ?>
<!-- Generated using onshape-to-robot -->
<!-- Onshape document_id: 4743a97557c0a80d1585b0a7 / workspace_id: 2d6986bf76e2e55acb049bf2 -->
<mujoco model="C:\Users\steph\code\arca\arca-sim\models\full\mjcf">
  <compiler angle="radian" meshdir="assets" autolimits="true"/>
  <default>
    <default class="C:\Users\steph\code\arca\arca-sim\models\full\mjcf">
      <joint frictionloss="0.1" armature="0.005"/>
      <position kp="50" dampratio="1"/>
      <default class="visual">
        <geom type="mesh" contype="0" conaffinity="0" group="2"/>
      </default>
      <default class="collision">
        <geom group="3"/>
      </default>
    </default>
  </default>
  <!-- Additional extras.xml -->
  <default>
    <equality solref="0.005 1"/>
  </default>
  <worldbody>
    <body name="world_link" pos="0 0 0" quat="1 0 0 0"/>
  </worldbody>
  <equality>
    <weld name="gantry" body1="world_link" body2="trunk" relpose="0 0 0.5 1 0 0 0"/>
  </equality>
  <worldbody>
    <!-- Link trunk -->
    <body name="trunk" pos="0 0 0" quat="1 0 0 0" childclass="C:\Users\steph\code\arca\arca-sim\models\full\mjcf">
      <freejoint name="trunk_freejoint"/>
      <inertial pos="-6.02596e-17 -2.1021e-06 -0.0342193" mass="0.50738" fullinertia="0.000361696 0.00154489 0.00155102 -6.30203e-08 -4.36525e-07 8.81145e-09"/>
      <!-- Part m2006_p36_3 -->
      <geom type="mesh" class="visual" pos="-0.01175 0.01425 -0.0386505" quat="0.298046 0.641224 -0.298046 -0.641224" mesh="m2006_p36_3" material="m2006_p36_3_material"/>
      <geom type="mesh" class="collision" pos="-0.01175 0.01425 -0.0386505" quat="0.298046 0.641224 -0.298046 -0.641224" mesh="m2006_p36_3" material="m2006_p36_3_material"/>
      <!-- Part upper_carriage -->
      <geom type="mesh" class="visual" pos="0.03225 1.43928e-15 -0.0893322" quat="0.5 0.5 0.5 0.5" mesh="upper_carriage" material="upper_carriage_material"/>
      <geom type="mesh" class="collision" pos="0.03225 1.43928e-15 -0.0893322" quat="0.5 0.5 0.5 0.5" mesh="upper_carriage" material="upper_carriage_material"/>
      <!-- Part m2006_p36_3_2 -->
      <geom type="mesh" class="visual" pos="0.09175 -0.01425 -0.0386505" quat="0.641224 0.298046 -0.641224 -0.298046" mesh="m2006_p36_3" material="m2006_p36_3_material"/>
      <geom type="mesh" class="collision" pos="0.09175 -0.01425 -0.0386505" quat="0.641224 0.298046 -0.641224 -0.298046" mesh="m2006_p36_3" material="m2006_p36_3_material"/>
      <!-- Part m2006_p36_3_3 -->
      <geom type="mesh" class="visual" pos="-0.09175 -0.01425 -0.0386505" quat="0.641224 0.298046 0.641224 0.298046" mesh="m2006_p36_3" material="m2006_p36_3_material"/>
      <geom type="mesh" class="collision" pos="-0.09175 -0.01425 -0.0386505" quat="0.641224 0.298046 0.641224 0.298046" mesh="m2006_p36_3" material="m2006_p36_3_material"/>
      <!-- Part superstructure -->
      <geom type="mesh" class="visual" pos="-0.07125 6.2454e-18 -0.0893322" quat="0.5 0.5 0.5 0.5" mesh="superstructure" material="superstructure_material"/>
      <geom type="mesh" class="collision" pos="-0.07125 6.2454e-18 -0.0893322" quat="0.5 0.5 0.5 0.5" mesh="superstructure" material="superstructure_material"/>
      <!-- Part m2006_p36_3_4 -->
      <geom type="mesh" class="visual" pos="0.01175 0.01425 -0.0386505" quat="0.298046 0.641224 0.298046 0.641224" mesh="m2006_p36_3" material="m2006_p36_3_material"/>
      <geom type="mesh" class="collision" pos="0.01175 0.01425 -0.0386505" quat="0.298046 0.641224 0.298046 0.641224" mesh="m2006_p36_3" material="m2006_p36_3_material"/>
      <!-- Part upper_carriage_2 -->
      <geom type="mesh" class="visual" pos="0.01775 5.97933e-16 -0.0893322" quat="0.5 0.5 0.5 0.5" mesh="upper_carriage__2" material="upper_carriage__2_material"/>
      <geom type="mesh" class="collision" pos="0.01775 5.97933e-16 -0.0893322" quat="0.5 0.5 0.5 0.5" mesh="upper_carriage__2" material="upper_carriage__2_material"/>
      <!-- Link thigh_lower_mount -->
      <body name="thigh_lower_mount" pos="0.05175 0.0275 -0.0893322" quat="5.35629e-15 -5.35602e-15 0.707107 0.707107">
        <!-- Joint from trunk to thigh_lower_mount -->
        <joint axis="0 0 1" name="l_hip_roll_passive" type="hinge"/>
        <inertial pos="-5.21214e-18 -1.75427e-05 -0.0275" mass="0.106222" fullinertia="4.98391e-05 6.15836e-05 4.69705e-05 7.51378e-21 -2.14174e-13 4.25849e-13"/>
        <!-- Part 6656k118_ultra_thin_ball_bearing -->
        <geom type="mesh" class="visual" pos="0.0195 2.77556e-17 -0.0275" quat="7.85046e-17 -0.707107 -2.22045e-16 -0.707107" mesh="6656k118_ultra_thin_ball_bearing" material="6656k118_ultra_thin_ball_bearing_material"/>
        <geom type="mesh" class="collision" pos="0.0195 2.77556e-17 -0.0275" quat="7.85046e-17 -0.707107 -2.22045e-16 -0.707107" mesh="6656k118_ultra_thin_ball_bearing" material="6656k118_ultra_thin_ball_bearing_material"/>
        <!-- Part 5972k222_ball_bearing -->
        <geom type="mesh" class="visual" pos="-2.08167e-17 0 -0.0515" quat="5.55112e-17 -4.85723e-17 1 -1.11022e-16" mesh="5972k222_ball_bearing" material="5972k222_ball_bearing_material"/>
        <geom type="mesh" class="collision" pos="-2.08167e-17 0 -0.0515" quat="5.55112e-17 -4.85723e-17 1 -1.11022e-16" mesh="5972k222_ball_bearing" material="5972k222_ball_bearing_material"/>
        <!-- Part 6656k118_ultra_thin_ball_bearing_2 -->
        <geom type="mesh" class="visual" pos="-0.0195 0 -0.0275" quat="0.707107 0 -0.707107 1.17757e-16" mesh="6656k118_ultra_thin_ball_bearing" material="6656k118_ultra_thin_ball_bearing_material"/>
        <geom type="mesh" class="collision" pos="-0.0195 0 -0.0275" quat="0.707107 0 -0.707107 1.17757e-16" mesh="6656k118_ultra_thin_ball_bearing" material="6656k118_ultra_thin_ball_bearing_material"/>
        <!-- Part 5972k222_ball_bearing_2 -->
        <geom type="mesh" class="visual" pos="0 -1.38778e-17 -0.0035" quat="1 0 0 0" mesh="5972k222_ball_bearing" material="5972k222_ball_bearing_material"/>
        <geom type="mesh" class="collision" pos="0 -1.38778e-17 -0.0035" quat="1 0 0 0" mesh="5972k222_ball_bearing" material="5972k222_ball_bearing_material"/>
        <!-- Part lower_carriage -->
        <geom type="mesh" class="visual" pos="0.0195 2.77556e-17 -0.0275" quat="0.707107 -0 -0.707107 2.22045e-16" mesh="lower_carriage" material="lower_carriage_material"/>
        <geom type="mesh" class="collision" pos="0.0195 2.77556e-17 -0.0275" quat="0.707107 -0 -0.707107 2.22045e-16" mesh="lower_carriage" material="lower_carriage_material"/>
        <!-- Link l_thigh -->
        <body name="l_thigh" pos="-0.02275 0 -0.0275" quat="0.270598 0.653281 0.270598 0.653281">
          <!-- Joint from thigh_lower_mount to l_thigh -->
          <joint axis="0 0 1" name="l_hip_pitch_passive" type="hinge"/>
          <inertial pos="0.000899952 0.0298613 0.0179928" mass="0.15874" fullinertia="0.000394916 6.10091e-05 0.00035582 2.95051e-06 2.80027e-07 4.27413e-07"/>
          <!-- Part 5972k222_ball_bearing_3 -->
          <geom type="mesh" class="visual" pos="2.77556e-17 0.12 -8.32667e-17" quat="6.66134e-16 1.30648e-16 -1 9.99201e-16" mesh="5972k222_ball_bearing" material="5972k222_ball_bearing_material"/>
          <geom type="mesh" class="collision" pos="2.77556e-17 0.12 -8.32667e-17" quat="6.66134e-16 1.30648e-16 -1 9.99201e-16" mesh="5972k222_ball_bearing" material="5972k222_ball_bearing_material"/>
          <!-- Part l_outer_arm -->
          <geom type="mesh" class="visual" pos="4.16334e-17 6.93889e-17 -0.018" quat="3.42841e-16 1 8.12942e-18 8.17588e-17" mesh="l_outer_arm" material="l_outer_arm_material"/>
          <geom type="mesh" class="collision" pos="4.16334e-17 6.93889e-17 -0.018" quat="3.42841e-16 1 8.12942e-18 8.17588e-17" mesh="l_outer_arm" material="l_outer_arm_material"/>
          <!-- Part 59935k13_ball_joint_rod_end -->
          <geom type="mesh" class="visual" pos="0.0384801 0.01472 0.0591261" quat="0.00186181 -0.707094 0.707114 0.00185503" mesh="59935k13_ball_joint_rod_end" material="59935k13_ball_joint_rod_end_material"/>
          <geom type="mesh" class="collision" pos="0.0384801 0.01472 0.0591261" quat="0.00186181 -0.707094 0.707114 0.00185503" mesh="59935k13_ball_joint_rod_end" material="59935k13_ball_joint_rod_end_material"/>
          <!-- Part l_inner_plate -->
          <geom type="mesh" class="visual" pos="-3.58456e-07 0.00012709 -0.0181521" quat="1.39445e-05 -4.79387e-06 -0.0026282 0.999997" mesh="l_inner_plate" material="l_inner_plate_material"/>
          <geom type="mesh" class="collision" pos="-3.58456e-07 0.00012709 -0.0181521" quat="1.39445e-05 -4.79387e-06 -0.0026282 0.999997" mesh="l_inner_plate" material="l_inner_plate_material"/>
          <!-- Part l_inner_arm -->
          <geom type="mesh" class="visual" pos="-3.58456e-07 0.00012709 -0.0181521" quat="0.0026282 -0.999997 1.39445e-05 -4.79387e-06" mesh="l_inner_arm" material="l_inner_arm_material"/>
          <geom type="mesh" class="collision" pos="-3.58456e-07 0.00012709 -0.0181521" quat="0.0026282 -0.999997 1.39445e-05 -4.79387e-06" mesh="l_inner_arm" material="l_inner_arm_material"/>
          <!-- Part 5972k222_ball_bearing_4 -->
          <geom type="mesh" class="visual" pos="2.46591e-06 0.119843 0.036228" quat="1.39445e-05 -4.79387e-06 -0.0026282 0.999997" mesh="5972k222_ball_bearing" material="5972k222_ball_bearing_material"/>
          <geom type="mesh" class="collision" pos="2.46591e-06 0.119843 0.036228" quat="1.39445e-05 -4.79387e-06 -0.0026282 0.999997" mesh="5972k222_ball_bearing" material="5972k222_ball_bearing_material"/>
          <!-- Part m2006_p36_3_5 -->
          <geom type="mesh" class="visual" pos="1.38778e-17 2.77556e-17 -0.018" quat="0.34202 -5.36493e-16 -3.33067e-16 -0.939693" mesh="m2006_p36_3__2" material="m2006_p36_3__2_material"/>
          <geom type="mesh" class="collision" pos="1.38778e-17 2.77556e-17 -0.018" quat="0.34202 -5.36493e-16 -3.33067e-16 -0.939693" mesh="m2006_p36_3__2" material="m2006_p36_3__2_material"/>
          <!-- Part l_outer_plate -->
          <geom type="mesh" class="visual" pos="1.38778e-17 2.77556e-17 -0.018" quat="1.86399e-17 1.66533e-16 5.55112e-16 1" mesh="l_outer_plate" material="l_outer_plate_material"/>
          <geom type="mesh" class="collision" pos="1.38778e-17 2.77556e-17 -0.018" quat="1.86399e-17 1.66533e-16 5.55112e-16 1" mesh="l_outer_plate" material="l_outer_plate_material"/>
          <!-- Part 59935k13_ball_joint_rod_end_2 -->
          <geom type="mesh" class="visual" pos="0.0134808 0.015 -0.01345" quat="0.707107 -0 -1.38778e-17 -0.707107" mesh="59935k13_ball_joint_rod_end" material="59935k13_ball_joint_rod_end_material"/>
          <geom type="mesh" class="collision" pos="0.0134808 0.015 -0.01345" quat="0.707107 -0 -1.38778e-17 -0.707107" mesh="59935k13_ball_joint_rod_end" material="59935k13_ball_joint_rod_end_material"/>
          <!-- Part standoff -->
          <geom type="mesh" class="visual" pos="-8.32667e-17 -1.11022e-16 -0.018" quat="5.82867e-16 1.2106e-15 -3.33067e-16 1" mesh="standoff" material="standoff_material"/>
          <geom type="mesh" class="collision" pos="-8.32667e-17 -1.11022e-16 -0.018" quat="5.82867e-16 1.2106e-15 -3.33067e-16 1" mesh="standoff" material="standoff_material"/>
          <!-- Frame closing_l_hip_inner_2 -->
          <site group="3" name="closing_l_hip_inner_2" pos="0.0259801 0.0147204 0.059126" quat="0.49868 0.501322 0.501303 -0.498689"/>
          <!-- Frame closing_l_hip_outer_2 -->
          <site group="3" name="closing_l_hip_outer_2" pos="0.0259808 0.015 -0.01345" quat="0.5 -0.5 0.5 0.5"/>
          <!-- Link l_knee -->
          <body name="l_knee" pos="2.49973e-06 0.119861 0.032728" quat="0.707094 0.00186181 0.00185503 -0.707114">
            <!-- Joint from l_thigh to l_knee -->
            <joint axis="0 0 1" name="l_knee_passive" type="hinge"/>
            <inertial pos="0.00122988 -0.0428518 -0.016707" mass="0.0251199" fullinertia="4.11528e-05 4.86011e-06 3.88399e-05 -2.3273e-07 4.94116e-07 5.96743e-07"/>
            <!-- Part ankle -->
            <geom type="mesh" class="visual" pos="-2.77556e-17 0 -0.0018" quat="0.5 -0.5 -0.5 -0.5" mesh="ankle" material="ankle_material"/>
            <geom type="mesh" class="collision" pos="-2.77556e-17 0 -0.0018" quat="0.5 -0.5 -0.5 -0.5" mesh="ankle" material="ankle_material"/>
            <!-- Part ankle_2 -->
            <geom type="mesh" class="visual" pos="-5.55112e-17 -1.38778e-17 -0.0018" quat="0.5 -0.5 -0.5 -0.5" mesh="ankle__2" material="ankle__2_material"/>
            <geom type="mesh" class="collision" pos="-5.55112e-17 -1.38778e-17 -0.0018" quat="0.5 -0.5 -0.5 -0.5" mesh="ankle__2" material="ankle__2_material"/>
            <!-- Part part_3 -->
            <geom type="mesh" class="visual" pos="-1.4988e-15 -1.66533e-16 -0.0272" quat="0.5 -0.5 0.5 0.5" mesh="part_3" material="part_3_material"/>
            <geom type="mesh" class="collision" pos="-1.4988e-15 -1.66533e-16 -0.0272" quat="0.5 -0.5 0.5 0.5" mesh="part_3" material="part_3_material"/>
            <!-- Part 59935k13_ball_joint_rod_end_3 -->
            <geom type="mesh" class="visual" pos="0.0294047 -0.0362523 -0.0344" quat="0.707107 3.43294e-16 -2.14412e-15 0.707107" mesh="59935k13_ball_joint_rod_end" material="59935k13_ball_joint_rod_end_material"/>
            <geom type="mesh" class="collision" pos="0.0294047 -0.0362523 -0.0344" quat="0.707107 3.43294e-16 -2.14412e-15 0.707107" mesh="59935k13_ball_joint_rod_end" material="59935k13_ball_joint_rod_end_material"/>
            <!-- Frame closing_l_knee_linkage_2 -->
            <site group="3" name="closing_l_knee_linkage_2" pos="0.0169047 -0.0362523 -0.0344" quat="0.5 0.5 0.5 -0.5"/>
            <!-- Link l_foot -->
            <body name="l_foot" pos="-8.32667e-17 -0.12 -0.0195" quat="1.36686e-16 0.382683 0.92388 -1.22539e-16">
              <!-- Joint from l_knee to l_foot -->
              <joint axis="0 0 1" name="l_ankle_passive" type="hinge"/>
              <inertial pos="-8.30386e-08 -0.00450828 -0.005" mass="0.00685832" fullinertia="2.75437e-07 9.89038e-07 1.15532e-06 8.01075e-13 -5.40036e-13 1.74194e-14"/>
              <!-- Part foot -->
              <geom type="mesh" class="visual" pos="0 0 -0.005" quat="0.707107 -0.707107 0 -1.57713e-20" mesh="foot" material="foot_material"/>
              <geom type="mesh" class="collision" pos="0 0 -0.005" quat="0.707107 -0.707107 0 -1.57713e-20" mesh="foot" material="foot_material"/>
            </body>
          </body>
          <!-- Link knee_arm__length_0_04_meter -->
          <body name="knee_arm__length_0_04_meter" pos="1.38778e-17 2.77556e-17 -0.018" quat="0.34202 -5.34587e-16 1.11022e-16 -0.939693">
            <!-- Joint from l_thigh to knee_arm__length_0_04_meter -->
            <joint axis="0 0 1" name="l_knee" type="hinge" range="-1.307131438305153 1.83446121528464"/>
            <inertial pos="0.0192583 -0.00522325 0.0091877" mass="0.00480721" fullinertia="1.96137e-07 1.3472e-06 1.41312e-06 3.3253e-07 -2.06002e-07 5.48122e-08"/>
            <!-- Part 59935k13_ball_joint_rod_end_4 -->
            <geom type="mesh" class="visual" pos="0.0353599 -0.0224928 0.013825" quat="4.70139e-16 -0.131451 -0.991323 -2.63024e-16" mesh="59935k13_ball_joint_rod_end" material="59935k13_ball_joint_rod_end_material"/>
            <geom type="mesh" class="collision" pos="0.0353599 -0.0224928 0.013825" quat="4.70139e-16 -0.131451 -0.991323 -2.63024e-16" mesh="59935k13_ball_joint_rod_end" material="59935k13_ball_joint_rod_end_material"/>
            <!-- Part hip_arm__length_0_04_meter -->
            <geom type="mesh" class="visual" pos="-8.67362e-19 1.38778e-17 1.38778e-17" quat="0.131451 -1.4918e-15 8.10463e-15 0.991323" mesh="hip_arm__length_0_04_meter" material="hip_arm__length_0_04_meter_material"/>
            <geom type="mesh" class="collision" pos="-8.67362e-19 1.38778e-17 1.38778e-17" quat="0.131451 -1.4918e-15 8.10463e-15 0.991323" mesh="hip_arm__length_0_04_meter" material="hip_arm__length_0_04_meter_material"/>
            <!-- Link l_knee_passive_link_x -->
            <body name="l_knee_passive_link_x" pos="0.0386177 -0.0104248 0.013825" quat="0.41209 0.807229 0.381279 0.182181">
              <!-- Joint from knee_arm__length_0_04_meter to l_knee_passive_link_x -->
              <joint axis="1 0 0" name="l_knee_passive_x" type="hinge"/>
              <inertial pos="0 0 0" mass="1e-09" fullinertia="1e-09 1e-09 1e-09 0 0 0"/>
              <!-- Link l_knee_passive_link_y -->
              <body name="l_knee_passive_link_y" pos="0 2.51535e-17 -2.77556e-17" quat="1 -1.19718e-17 1.11022e-16 -5.55112e-17">
                <!-- Joint from l_knee_passive_link_x to l_knee_passive_link_y -->
                <joint axis="0 1 0" name="l_knee_passive_y" type="hinge"/>
                <inertial pos="0 0 0" mass="1e-09" fullinertia="1e-09 1e-09 1e-09 0 0 0"/>
                <!-- Link linkage__configuration_default_length_0_12_meter -->
                <body name="linkage__configuration_default_length_0_12_meter" pos="0 2.51535e-17 -2.77556e-17" quat="1 -1.19718e-17 1.11022e-16 -5.55112e-17">
                  <!-- Joint from l_knee_passive_link_y to linkage__configuration_default_length_0_12_meter -->
                  <joint axis="0 0 1" name="l_knee_passive_z" type="hinge"/>
                  <inertial pos="-0.06 -5.19278e-09 -5.28481e-17" mass="0.00554627" fullinertia="1.40646e-08 5.38143e-06 5.37746e-06 7.76078e-22 -9.69161e-12 1.67044e-21"/>
                  <!-- Part 59935k13_ball_joint_rod_end_5 -->
                  <geom type="mesh" class="visual" pos="-0.0125 1.64799e-17 0" quat="0.5 -0.5 -0.5 -0.5" mesh="59935k13_ball_joint_rod_end__2" material="59935k13_ball_joint_rod_end__2_material"/>
                  <geom type="mesh" class="collision" pos="-0.0125 1.64799e-17 0" quat="0.5 -0.5 -0.5 -0.5" mesh="59935k13_ball_joint_rod_end__2" material="59935k13_ball_joint_rod_end__2_material"/>
                  <!-- Part part_3__length_0_12_meter -->
                  <geom type="mesh" class="visual" pos="-0.0125 1.21431e-17 -5.55112e-17" quat="0.5 -0.5 -0.5 -0.5" mesh="part_3__length_0_12_meter" material="part_3__length_0_12_meter_material"/>
                  <geom type="mesh" class="collision" pos="-0.0125 1.21431e-17 -5.55112e-17" quat="0.5 -0.5 -0.5 -0.5" mesh="part_3__length_0_12_meter" material="part_3__length_0_12_meter_material"/>
                  <!-- Part 59935k13_ball_joint_rod_end_6 -->
                  <geom type="mesh" class="visual" pos="-0.1075 3.90313e-17 -8.32667e-17" quat="0.5 -0.5 0.5 0.5" mesh="59935k13_ball_joint_rod_end__2" material="59935k13_ball_joint_rod_end__2_material"/>
                  <geom type="mesh" class="collision" pos="-0.1075 3.90313e-17 -8.32667e-17" quat="0.5 -0.5 0.5 0.5" mesh="59935k13_ball_joint_rod_end__2" material="59935k13_ball_joint_rod_end__2_material"/>
                  <!-- Frame closing_l_knee_linkage_1 -->
                  <site group="3" name="closing_l_knee_linkage_1" pos="-0.12 5.0307e-17 -5.55112e-17" quat="2.22045e-16 -3.2204e-18 -1 -2.22045e-16"/>
                </body>
              </body>
            </body>
          </body>
        </body>
      </body>
      <!-- Link r_thigh_lower_mount -->
      <body name="r_thigh_lower_mount" pos="-0.05175 0.0275 -0.0893322" quat="0.707107 -0.707107 -2.15383e-14 -2.14514e-14">
        <!-- Joint from trunk to r_thigh_lower_mount -->
        <joint axis="0 0 1" name="r_hip_roll_passive" type="hinge"/>
        <inertial pos="9.20457e-18 -1.75427e-05 -0.0275" mass="0.106222" fullinertia="4.98391e-05 6.15836e-05 4.69705e-05 -7.73949e-21 -2.14174e-13 4.25849e-13"/>
        <!-- Part 6656k118_ultra_thin_ball_bearing_3 -->
        <geom type="mesh" class="visual" pos="0.0195 1.38778e-17 -0.0275" quat="5.88785e-17 0.707107 0 0.707107" mesh="6656k118_ultra_thin_ball_bearing" material="6656k118_ultra_thin_ball_bearing_material"/>
        <geom type="mesh" class="collision" pos="0.0195 1.38778e-17 -0.0275" quat="5.88785e-17 0.707107 0 0.707107" mesh="6656k118_ultra_thin_ball_bearing" material="6656k118_ultra_thin_ball_bearing_material"/>
        <!-- Part 5972k222_ball_bearing_5 -->
        <geom type="mesh" class="visual" pos="1.38778e-17 -1.38778e-17 -0.0515" quat="0 0 -1 1.44946e-16" mesh="5972k222_ball_bearing" material="5972k222_ball_bearing_material"/>
        <geom type="mesh" class="collision" pos="1.38778e-17 -1.38778e-17 -0.0515" quat="0 0 -1 1.44946e-16" mesh="5972k222_ball_bearing" material="5972k222_ball_bearing_material"/>
        <!-- Part 6656k118_ultra_thin_ball_bearing_4 -->
        <geom type="mesh" class="visual" pos="-0.0195 1.38778e-17 -0.0275" quat="0.707107 2.19573e-17 -0.707107 5.55112e-17" mesh="6656k118_ultra_thin_ball_bearing" material="6656k118_ultra_thin_ball_bearing_material"/>
        <geom type="mesh" class="collision" pos="-0.0195 1.38778e-17 -0.0275" quat="0.707107 2.19573e-17 -0.707107 5.55112e-17" mesh="6656k118_ultra_thin_ball_bearing" material="6656k118_ultra_thin_ball_bearing_material"/>
        <!-- Part 5972k222_ball_bearing_6 -->
        <geom type="mesh" class="visual" pos="0 0 -0.0035" quat="1 -0 -0 8.58281e-28" mesh="5972k222_ball_bearing" material="5972k222_ball_bearing_material"/>
        <geom type="mesh" class="collision" pos="0 0 -0.0035" quat="1 -0 -0 8.58281e-28" mesh="5972k222_ball_bearing" material="5972k222_ball_bearing_material"/>
        <!-- Part lower_carriage_2 -->
        <geom type="mesh" class="visual" pos="0.0195 0 -0.0275" quat="0.707107 -4.97743e-17 -0.707107 -1.38778e-16" mesh="lower_carriage" material="lower_carriage_material"/>
        <geom type="mesh" class="collision" pos="0.0195 0 -0.0275" quat="0.707107 -4.97743e-17 -0.707107 -1.38778e-16" mesh="lower_carriage" material="lower_carriage_material"/>
        <!-- Link r_thigh -->
        <body name="r_thigh" pos="-0.02275 -1.38778e-17 -0.0275" quat="0.653281 0.270598 0.653281 0.270598">
          <!-- Joint from r_thigh_lower_mount to r_thigh -->
          <joint axis="0 0 1" name="r_hip_pitch_passive" type="hinge"/>
          <inertial pos="-0.000931108 0.0298878 0.0179928" mass="0.15874" fullinertia="0.000394556 6.11092e-05 0.000355559 -3.13013e-06 -2.2953e-07 3.84008e-07"/>
          <!-- Part 59935k13_ball_joint_rod_end_7 -->
          <geom type="mesh" class="visual" pos="-0.0134814 0.0147215 0.0591256" quat="0.00186181 -0.707094 0.707114 0.00185503" mesh="59935k13_ball_joint_rod_end" material="59935k13_ball_joint_rod_end_material"/>
          <geom type="mesh" class="collision" pos="-0.0134814 0.0147215 0.0591256" quat="0.00186181 -0.707094 0.707114 0.00185503" mesh="59935k13_ball_joint_rod_end" material="59935k13_ball_joint_rod_end_material"/>
          <!-- Part standoff_2 -->
          <geom type="mesh" class="visual" pos="-2.77556e-17 6.93889e-17 -0.018" quat="0 -3.37434e-16 -1.11022e-16 -1" mesh="standoff" material="standoff_material"/>
          <geom type="mesh" class="collision" pos="-2.77556e-17 6.93889e-17 -0.018" quat="0 -3.37434e-16 -1.11022e-16 -1" mesh="standoff" material="standoff_material"/>
          <!-- Part 59935k13_ball_joint_rod_end_8 -->
          <geom type="mesh" class="visual" pos="-0.0384808 0.015 -0.01345" quat="0.707107 1.28343e-16 -0 -0.707107" mesh="59935k13_ball_joint_rod_end" material="59935k13_ball_joint_rod_end_material"/>
          <geom type="mesh" class="collision" pos="-0.0384808 0.015 -0.01345" quat="0.707107 1.28343e-16 -0 -0.707107" mesh="59935k13_ball_joint_rod_end" material="59935k13_ball_joint_rod_end_material"/>
          <!-- Part 5972k222_ball_bearing_7 -->
          <geom type="mesh" class="visual" pos="2.46591e-06 0.119843 0.036228" quat="1.39445e-05 -4.79387e-06 -0.0026282 0.999997" mesh="5972k222_ball_bearing" material="5972k222_ball_bearing_material"/>
          <geom type="mesh" class="collision" pos="2.46591e-06 0.119843 0.036228" quat="1.39445e-05 -4.79387e-06 -0.0026282 0.999997" mesh="5972k222_ball_bearing" material="5972k222_ball_bearing_material"/>
          <!-- Part m2006_p36_3_6 -->
          <geom type="mesh" class="visual" pos="-2.77556e-17 1.38778e-17 -0.018" quat="0.34202 3.42138e-16 -1.11022e-16 0.939693" mesh="m2006_p36_3" material="m2006_p36_3_material"/>
          <geom type="mesh" class="collision" pos="-2.77556e-17 1.38778e-17 -0.018" quat="0.34202 3.42138e-16 -1.11022e-16 0.939693" mesh="m2006_p36_3" material="m2006_p36_3_material"/>
          <!-- Part 5972k222_ball_bearing_8 -->
          <geom type="mesh" class="visual" pos="-1.38778e-17 0.12 -8.32667e-17" quat="3.63603e-16 1 1.46907e-16 2.97807e-18" mesh="5972k222_ball_bearing" material="5972k222_ball_bearing_material"/>
          <geom type="mesh" class="collision" pos="-1.38778e-17 0.12 -8.32667e-17" quat="3.63603e-16 1 1.46907e-16 2.97807e-18" mesh="5972k222_ball_bearing" material="5972k222_ball_bearing_material"/>
          <!-- Part r_thigh_outer_plate -->
          <geom type="mesh" class="visual" pos="-1.38778e-17 1.38778e-17 -0.018" quat="3.05191e-16 1 1.47911e-29 2.09346e-16" mesh="r_thigh_outer_plate" material="r_thigh_outer_plate_material"/>
          <geom type="mesh" class="collision" pos="-1.38778e-17 1.38778e-17 -0.018" quat="3.05191e-16 1 1.47911e-29 2.09346e-16" mesh="r_thigh_outer_plate" material="r_thigh_outer_plate_material"/>
          <!-- Part r_outer_arm -->
          <geom type="mesh" class="visual" pos="0 -2.77556e-17 -0.018" quat="1.43548e-16 2.65852e-18 -1.68268e-16 -1" mesh="r_outer_arm" material="r_outer_arm_material"/>
          <geom type="mesh" class="collision" pos="0 -2.77556e-17 -0.018" quat="1.43548e-16 2.65852e-18 -1.68268e-16 -1" mesh="r_outer_arm" material="r_outer_arm_material"/>
          <!-- Part r_inner_arm -->
          <geom type="mesh" class="visual" pos="-3.58456e-07 0.00012709 -0.0181521" quat="1.39445e-05 -4.79387e-06 -0.0026282 0.999997" mesh="r_inner_arm" material="r_inner_arm_material"/>
          <geom type="mesh" class="collision" pos="-3.58456e-07 0.00012709 -0.0181521" quat="1.39445e-05 -4.79387e-06 -0.0026282 0.999997" mesh="r_inner_arm" material="r_inner_arm_material"/>
          <!-- Part l_inner_plate_2 -->
          <geom type="mesh" class="visual" pos="-3.58456e-07 0.00012709 -0.0181521" quat="1.39445e-05 -4.79387e-06 -0.0026282 0.999997" mesh="l_inner_plate" material="l_inner_plate_material"/>
          <geom type="mesh" class="collision" pos="-3.58456e-07 0.00012709 -0.0181521" quat="1.39445e-05 -4.79387e-06 -0.0026282 0.999997" mesh="l_inner_plate" material="l_inner_plate_material"/>
          <!-- Frame closing_r_hip_outer_2 -->
          <site group="3" name="closing_r_hip_outer_2" pos="-0.0259808 0.015 -0.01345" quat="0.707107 0.707107 2.22045e-16 2.53355e-16"/>
          <!-- Frame closing_r_hip_inner_2 -->
          <site group="3" name="closing_r_hip_inner_2" pos="-0.0259814 0.0147218 0.0591255" quat="0.708963 -0.705246 6.47048e-06 -1.325e-05"/>
          <!-- Link r_knee -->
          <body name="r_knee" pos="2.49973e-06 0.119861 0.032728" quat="0.707114 0.00185503 -0.00186181 0.707094">
            <!-- Joint from r_thigh to r_knee -->
            <joint axis="0 0 1" name="r_knee_passive" type="hinge"/>
            <inertial pos="-0.00122513 -0.0428542 -0.0167069" mass="0.0251199" fullinertia="4.1152e-05 4.85627e-06 3.88354e-05 2.31027e-07 -4.92054e-07 5.95733e-07"/>
            <!-- Part ankle_3 -->
            <geom type="mesh" class="visual" pos="0 2.77556e-17 -0.0018" quat="0.5 -0.5 -0.5 -0.5" mesh="ankle__2" material="ankle__2_material"/>
            <geom type="mesh" class="collision" pos="0 2.77556e-17 -0.0018" quat="0.5 -0.5 -0.5 -0.5" mesh="ankle__2" material="ankle__2_material"/>
            <!-- Part ankle_4 -->
            <geom type="mesh" class="visual" pos="-2.77556e-17 1.38778e-17 -0.0018" quat="0.5 -0.5 -0.5 -0.5" mesh="ankle" material="ankle_material"/>
            <geom type="mesh" class="collision" pos="-2.77556e-17 1.38778e-17 -0.0018" quat="0.5 -0.5 -0.5 -0.5" mesh="ankle" material="ankle_material"/>
            <!-- Part part_3_2 -->
            <geom type="mesh" class="visual" pos="2.77556e-17 2.77556e-17 -0.03195" quat="0.5 -0.5 -0.5 -0.5" mesh="part_3" material="part_3_material"/>
            <geom type="mesh" class="collision" pos="2.77556e-17 2.77556e-17 -0.03195" quat="0.5 -0.5 -0.5 -0.5" mesh="part_3" material="part_3_material"/>
            <!-- Part 59935k13_ball_joint_rod_end_9 -->
            <geom type="mesh" class="visual" pos="-0.00505927 -0.0405432 -0.0338278" quat="0.818249 -0.0201004 -0.0110332 0.574407" mesh="59935k13_ball_joint_rod_end" material="59935k13_ball_joint_rod_end_material"/>
            <geom type="mesh" class="collision" pos="-0.00505927 -0.0405432 -0.0338278" quat="0.818249 -0.0201004 -0.0110332 0.574407" mesh="59935k13_ball_joint_rod_end" material="59935k13_ball_joint_rod_end_material"/>
            <!-- Frame closing_r_knee_1 -->
            <site group="3" name="closing_r_knee_1" pos="-0.0168039 -0.0363018 -0.0343974" quat="0.137488 0.106354 0.700861 0.691794"/>
            <!-- Link r_foot -->
            <body name="r_foot" pos="2.77556e-17 -0.12 -0.0195" quat="3.99431e-16 1 1.34619e-17 3.14051e-16">
              <!-- Joint from r_knee to r_foot -->
              <joint axis="0 0 1" name="r_ankle_passive" type="hinge"/>
              <inertial pos="0.00318789 0.00318778 -0.005" mass="0.00685832" fullinertia="6.32238e-07 6.32237e-07 1.15532e-06 3.568e-07 3.69545e-13 -3.9418e-13"/>
              <!-- Part foot_2 -->
              <geom type="mesh" class="visual" pos="5.55112e-17 8.32667e-17 -0.005" quat="0.270598 -0.270598 -0.653281 0.653281" mesh="foot" material="foot_material"/>
              <geom type="mesh" class="collision" pos="5.55112e-17 8.32667e-17 -0.005" quat="0.270598 -0.270598 -0.653281 0.653281" mesh="foot" material="foot_material"/>
            </body>
          </body>
          <!-- Link knee_arm__length_0_04_meter_2 -->
          <body name="knee_arm__length_0_04_meter_2" pos="-2.8365e-05 -3.38041e-05 -0.018" quat="0.34202 3.19859e-17 -1.52656e-16 0.939693">
            <!-- Joint from r_thigh to knee_arm__length_0_04_meter_2 -->
            <joint axis="0 0 1" name="r_knee" type="hinge"/>
            <inertial pos="-0.0192516 -0.005248 0.0091877" mass="0.00480721" fullinertia="2.0089e-07 1.34244e-06 1.41312e-06 -3.40624e-07 2.05393e-07 5.70504e-08"/>
            <!-- Part 59935k13_ball_joint_rod_end_10 -->
            <geom type="mesh" class="visual" pos="-0.0418811 0.00149022 0.013825" quat="1.22814e-15 -0.991081 -0.133261 -8.8858e-16" mesh="59935k13_ball_joint_rod_end" material="59935k13_ball_joint_rod_end_material"/>
            <geom type="mesh" class="collision" pos="-0.0418811 0.00149022 0.013825" quat="1.22814e-15 -0.991081 -0.133261 -8.8858e-16" mesh="59935k13_ball_joint_rod_end" material="59935k13_ball_joint_rod_end_material"/>
            <!-- Part hip_arm__length_0_04_meter_2 -->
            <geom type="mesh" class="visual" pos="0 0 0" quat="0.991081 1.17864e-15 -8.88178e-16 0.133261" mesh="hip_arm__length_0_04_meter" material="hip_arm__length_0_04_meter_material"/>
            <geom type="mesh" class="collision" pos="0 0 0" quat="0.991081 1.17864e-15 -8.88178e-16 0.133261" mesh="hip_arm__length_0_04_meter" material="hip_arm__length_0_04_meter_material"/>
            <!-- Link r_knee_passive_link_x -->
            <body name="r_knee_passive_link_x" pos="-0.0385793 -0.0105658 0.013825" quat="0.399182 0.138871 0.320197 0.847846">
              <!-- Joint from knee_arm__length_0_04_meter_2 to r_knee_passive_link_x -->
              <joint axis="1 0 0" name="r_knee_passive_x" type="hinge"/>
              <inertial pos="0 0 0" mass="1e-09" fullinertia="1e-09 1e-09 1e-09 0 0 0"/>
              <!-- Link r_knee_passive_link_y -->
              <body name="r_knee_passive_link_y" pos="0 1.04083e-17 0" quat="1 -1.35123e-17 -3.33067e-16 2.77556e-16">
                <!-- Joint from r_knee_passive_link_x to r_knee_passive_link_y -->
                <joint axis="0 1 0" name="r_knee_passive_y" type="hinge"/>
                <inertial pos="0 0 0" mass="1e-09" fullinertia="1e-09 1e-09 1e-09 0 0 0"/>
                <!-- Link linkage__configuration_default_length_0_12_meter_2 -->
                <body name="linkage__configuration_default_length_0_12_meter_2" pos="0 1.04083e-17 0" quat="1 -1.35123e-17 -3.33067e-16 2.77556e-16">
                  <!-- Joint from r_knee_passive_link_y to linkage__configuration_default_length_0_12_meter_2 -->
                  <joint axis="0 0 1" name="r_knee_passive_z" type="hinge"/>
                  <inertial pos="-0.06 -5.19278e-09 -2.62716e-17" mass="0.00554627" fullinertia="1.40646e-08 5.38143e-06 5.37746e-06 -3.94001e-22 -9.69161e-12 6.97487e-22"/>
                  <!-- Part 59935k13_ball_joint_rod_end_11 -->
                  <geom type="mesh" class="visual" pos="-0.1075 0 -8.32667e-17" quat="0.5 -0.5 0.5 0.5" mesh="59935k13_ball_joint_rod_end__2" material="59935k13_ball_joint_rod_end__2_material"/>
                  <geom type="mesh" class="collision" pos="-0.1075 0 -8.32667e-17" quat="0.5 -0.5 0.5 0.5" mesh="59935k13_ball_joint_rod_end__2" material="59935k13_ball_joint_rod_end__2_material"/>
                  <!-- Part part_3__length_0_12_meter_2 -->
                  <geom type="mesh" class="visual" pos="-0.1075 -3.46945e-18 -2.77556e-17" quat="0.5 -0.5 0.5 0.5" mesh="part_3__length_0_12_meter" material="part_3__length_0_12_meter_material"/>
                  <geom type="mesh" class="collision" pos="-0.1075 -3.46945e-18 -2.77556e-17" quat="0.5 -0.5 0.5 0.5" mesh="part_3__length_0_12_meter" material="part_3__length_0_12_meter_material"/>
                  <!-- Part 59935k13_ball_joint_rod_end_12 -->
                  <geom type="mesh" class="visual" pos="-0.0125 1.04083e-17 0" quat="0.5 -0.5 -0.5 -0.5" mesh="59935k13_ball_joint_rod_end__2" material="59935k13_ball_joint_rod_end__2_material"/>
                  <geom type="mesh" class="collision" pos="-0.0125 1.04083e-17 0" quat="0.5 -0.5 -0.5 -0.5" mesh="59935k13_ball_joint_rod_end__2" material="59935k13_ball_joint_rod_end__2_material"/>
                  <!-- Frame closing_r_knee_2 -->
                  <site group="3" name="closing_r_knee_2" pos="-0.12 -1.38778e-17 -5.55112e-17" quat="1 -4.67756e-17 -5.55112e-17 1.17094e-16"/>
                </body>
              </body>
            </body>
          </body>
        </body>
      </body>
      <!-- Link hip_arm__configuration_default -->
      <body name="hip_arm__configuration_default" pos="0.01175 0.01425 -0.0386505" quat="0.479206 0.519963 -0.479206 -0.519963">
        <!-- Joint from trunk to hip_arm__configuration_default -->
        <joint axis="0 0 1" name="l_hip_inner" type="hinge"/>
        <inertial pos="-0.0199541 -2.36213e-05 -0.00681107" mass="0.00480721" fullinertia="8.4118e-08 1.41349e-06 1.41312e-06 2.26557e-09 1.58559e-08 5.00559e-10"/>
        <!-- Part 59935k13_ball_joint_rod_end_13 -->
        <geom type="mesh" class="visual" pos="-0.04 0.0125 -0.004175" quat="1.20362e-15 1 -1.85022e-16 -2.0237e-15" mesh="59935k13_ball_joint_rod_end" material="59935k13_ball_joint_rod_end_material"/>
        <geom type="mesh" class="collision" pos="-0.04 0.0125 -0.004175" quat="1.20362e-15 1 -1.85022e-16 -2.0237e-15" mesh="59935k13_ball_joint_rod_end" material="59935k13_ball_joint_rod_end_material"/>
        <!-- Part hip_arm__length_0_04_meter_3 -->
        <geom type="mesh" class="visual" pos="0 0 0" quat="3.05191e-16 -1 6.86433e-19 2.09346e-16" mesh="hip_arm__length_0_04_meter" material="hip_arm__length_0_04_meter_material"/>
        <geom type="mesh" class="collision" pos="0 0 0" quat="3.05191e-16 -1 6.86433e-19 2.09346e-16" mesh="hip_arm__length_0_04_meter" material="hip_arm__length_0_04_meter_material"/>
        <!-- Link l_hip_inner_passive_link_x -->
        <body name="l_hip_inner_passive_link_x" pos="-0.04 0 -0.004175" quat="0.409324 0.237239 0.451343 0.756612">
          <!-- Joint from hip_arm__configuration_default to l_hip_inner_passive_link_x -->
          <joint axis="1 0 0" name="l_hip_inner_passive_x" type="hinge"/>
          <inertial pos="0 0 0" mass="1e-09" fullinertia="1e-09 1e-09 1e-09 0 0 0"/>
          <!-- Link l_hip_inner_passive_link_y -->
          <body name="l_hip_inner_passive_link_y" pos="2.60209e-18 3.46945e-18 0" quat="1 -2.22687e-17 1.11022e-16 -1.66533e-16">
            <!-- Joint from l_hip_inner_passive_link_x to l_hip_inner_passive_link_y -->
            <joint axis="0 1 0" name="l_hip_inner_passive_y" type="hinge"/>
            <inertial pos="0 0 0" mass="1e-09" fullinertia="1e-09 1e-09 1e-09 0 0 0"/>
            <!-- Link linkage__43d788dc267bdd7f4fb3b94dc32a7642 -->
            <body name="linkage__43d788dc267bdd7f4fb3b94dc32a7642" pos="2.60209e-18 3.46945e-18 0" quat="1 -2.22687e-17 1.11022e-16 -1.66533e-16">
              <!-- Joint from l_hip_inner_passive_link_y to linkage__43d788dc267bdd7f4fb3b94dc32a7642 -->
              <joint axis="0 0 1" name="l_hip_inner_passive_z" type="hinge"/>
              <inertial pos="-0.02625 -1.67941e-08 -3.69646e-17" mass="0.00171492" fullinertia="9.7543e-09 4.50395e-07 4.46417e-07 1.30595e-22 -2.26912e-12 1.59372e-22"/>
              <!-- Part 59935k13_ball_joint_rod_end_14 -->
              <geom type="mesh" class="visual" pos="-0.0125 0 0" quat="0.5 -0.5 -0.5 -0.5" mesh="59935k13_ball_joint_rod_end__2" material="59935k13_ball_joint_rod_end__2_material"/>
              <geom type="mesh" class="collision" pos="-0.0125 0 0" quat="0.5 -0.5 -0.5 -0.5" mesh="59935k13_ball_joint_rod_end__2" material="59935k13_ball_joint_rod_end__2_material"/>
              <!-- Part part_3__length_0_0525_meter -->
              <geom type="mesh" class="visual" pos="-0.0125 0 -4.16334e-17" quat="0.5 -0.5 -0.5 -0.5" mesh="part_3__length_0_0525_meter" material="part_3__length_0_0525_meter_material"/>
              <geom type="mesh" class="collision" pos="-0.0125 0 -4.16334e-17" quat="0.5 -0.5 -0.5 -0.5" mesh="part_3__length_0_0525_meter" material="part_3__length_0_0525_meter_material"/>
              <!-- Part 59935k13_ball_joint_rod_end_15 -->
              <geom type="mesh" class="visual" pos="-0.04 3.46945e-18 -6.93889e-17" quat="0.5 -0.5 0.5 0.5" mesh="59935k13_ball_joint_rod_end__2" material="59935k13_ball_joint_rod_end__2_material"/>
              <geom type="mesh" class="collision" pos="-0.04 3.46945e-18 -6.93889e-17" quat="0.5 -0.5 0.5 0.5" mesh="59935k13_ball_joint_rod_end__2" material="59935k13_ball_joint_rod_end__2_material"/>
              <!-- Frame closing_l_hip_inner_1 -->
              <site group="3" name="closing_l_hip_inner_1" pos="-0.0525 6.93889e-18 -6.93889e-17" quat="2.22045e-16 5.50144e-16 1 8.23994e-16"/>
            </body>
          </body>
        </body>
      </body>
      <!-- Link hip_arm__configuration_default_2 -->
      <body name="hip_arm__configuration_default_2" pos="0.09175 -0.01425 -0.0386505" quat="0.437314 0.555659 -0.437314 -0.555659">
        <!-- Joint from trunk to hip_arm__configuration_default_2 -->
        <joint axis="0 0 1" name="l_hip_outer" type="hinge"/>
        <inertial pos="-0.0199541 2.36213e-05 0.00681107" mass="0.00480721" fullinertia="8.4118e-08 1.41349e-06 1.41312e-06 -2.26557e-09 -1.58559e-08 5.00559e-10"/>
        <!-- Part 59935k13_ball_joint_rod_end_16 -->
        <geom type="mesh" class="visual" pos="-0.04 -0.0125 0.004175" quat="1 1.17166e-16 1.11022e-16 -0" mesh="59935k13_ball_joint_rod_end" material="59935k13_ball_joint_rod_end_material"/>
        <geom type="mesh" class="collision" pos="-0.04 -0.0125 0.004175" quat="1 1.17166e-16 1.11022e-16 -0" mesh="59935k13_ball_joint_rod_end" material="59935k13_ball_joint_rod_end_material"/>
        <!-- Part hip_arm__length_0_04_meter_4 -->
        <geom type="mesh" class="visual" pos="-3.46945e-18 6.93889e-18 0" quat="1 -0 -1.57772e-30 4.46455e-28" mesh="hip_arm__length_0_04_meter" material="hip_arm__length_0_04_meter_material"/>
        <geom type="mesh" class="collision" pos="-3.46945e-18 6.93889e-18 0" quat="1 -0 -1.57772e-30 4.46455e-28" mesh="hip_arm__length_0_04_meter" material="hip_arm__length_0_04_meter_material"/>
        <!-- Link l_hip_outer_passive_link_x -->
        <body name="l_hip_outer_passive_link_x" pos="-0.04 0 0.004175" quat="0.624319 -0.182676 -0.218553 0.727385">
          <!-- Joint from hip_arm__configuration_default_2 to l_hip_outer_passive_link_x -->
          <joint axis="1 0 0" name="l_hip_outer_passive_x" type="hinge"/>
          <inertial pos="0 0 0" mass="1e-09" fullinertia="1e-09 1e-09 1e-09 0 0 0"/>
          <!-- Link l_hip_outer_passive_link_y -->
          <body name="l_hip_outer_passive_link_y" pos="6.93889e-18 0 6.93889e-18" quat="1 0 1.11022e-16 -2.77556e-17">
            <!-- Joint from l_hip_outer_passive_link_x to l_hip_outer_passive_link_y -->
            <joint axis="0 1 0" name="l_hip_outer_passive_y" type="hinge"/>
            <inertial pos="0 0 0" mass="1e-09" fullinertia="1e-09 1e-09 1e-09 0 0 0"/>
            <!-- Link linkage__43d788dc267bdd7f4fb3b94dc32a7642_2 -->
            <body name="linkage__43d788dc267bdd7f4fb3b94dc32a7642_2" pos="6.93889e-18 0 6.93889e-18" quat="1 0 1.11022e-16 -2.77556e-17">
              <!-- Joint from l_hip_outer_passive_link_y to linkage__43d788dc267bdd7f4fb3b94dc32a7642_2 -->
              <joint axis="0 0 1" name="l_hip_outer_passive_z" type="hinge"/>
              <inertial pos="-0.02625 -1.67941e-08 -3.45542e-17" mass="0.00171492" fullinertia="9.7543e-09 4.50395e-07 4.46417e-07 1.62026e-22 -2.26912e-12 1.46392e-22"/>
              <!-- Part 59935k13_ball_joint_rod_end_17 -->
              <geom type="mesh" class="visual" pos="-0.04 1.38778e-17 -6.93889e-17" quat="0.5 -0.5 0.5 0.5" mesh="59935k13_ball_joint_rod_end__2" material="59935k13_ball_joint_rod_end__2_material"/>
              <geom type="mesh" class="collision" pos="-0.04 1.38778e-17 -6.93889e-17" quat="0.5 -0.5 0.5 0.5" mesh="59935k13_ball_joint_rod_end__2" material="59935k13_ball_joint_rod_end__2_material"/>
              <!-- Part part_3__length_0_0525_meter_2 -->
              <geom type="mesh" class="visual" pos="-0.04 1.38778e-17 -3.46945e-17" quat="0.5 -0.5 0.5 0.5" mesh="part_3__length_0_0525_meter" material="part_3__length_0_0525_meter_material"/>
              <geom type="mesh" class="collision" pos="-0.04 1.38778e-17 -3.46945e-17" quat="0.5 -0.5 0.5 0.5" mesh="part_3__length_0_0525_meter" material="part_3__length_0_0525_meter_material"/>
              <!-- Part 59935k13_ball_joint_rod_end_18 -->
              <geom type="mesh" class="visual" pos="-0.0125 0 0" quat="0.5 -0.5 -0.5 -0.5" mesh="59935k13_ball_joint_rod_end__2" material="59935k13_ball_joint_rod_end__2_material"/>
              <geom type="mesh" class="collision" pos="-0.0125 0 0" quat="0.5 -0.5 -0.5 -0.5" mesh="59935k13_ball_joint_rod_end__2" material="59935k13_ball_joint_rod_end__2_material"/>
              <!-- Frame closing_l_hip_outer_1 -->
              <site group="3" name="closing_l_hip_outer_1" pos="-0.0525 0 -8.32667e-17" quat="3.33067e-16 7.24032e-17 1 2.77556e-16"/>
            </body>
          </body>
        </body>
      </body>
      <!-- Link hip_arm__configuration_default_3 -->
      <body name="hip_arm__configuration_default_3" pos="-0.01175 0.01425 -0.0386505" quat="0.479199 0.519969 -0.479199 -0.519969">
        <!-- Joint from trunk to hip_arm__configuration_default_3 -->
        <joint axis="0 0 1" name="r_hip_inner" type="hinge"/>
        <inertial pos="-0.0199541 2.36213e-05 0.00681107" mass="0.00480721" fullinertia="8.4118e-08 1.41349e-06 1.41312e-06 -2.26557e-09 -1.58559e-08 5.00559e-10"/>
        <!-- Part 59935k13_ball_joint_rod_end_19 -->
        <geom type="mesh" class="visual" pos="-0.04 -0.0125 0.004175" quat="1 0 1.52656e-16 -6.93889e-17" mesh="59935k13_ball_joint_rod_end" material="59935k13_ball_joint_rod_end_material"/>
        <geom type="mesh" class="collision" pos="-0.04 -0.0125 0.004175" quat="1 0 1.52656e-16 -6.93889e-17" mesh="59935k13_ball_joint_rod_end" material="59935k13_ball_joint_rod_end_material"/>
        <!-- Part hip_arm__length_0_04_meter_5 -->
        <geom type="mesh" class="visual" pos="-1.73472e-18 0 -1.73472e-18" quat="1 0 4.38987e-20 -1.11022e-16" mesh="hip_arm__length_0_04_meter" material="hip_arm__length_0_04_meter_material"/>
        <geom type="mesh" class="collision" pos="-1.73472e-18 0 -1.73472e-18" quat="1 0 4.38987e-20 -1.11022e-16" mesh="hip_arm__length_0_04_meter" material="hip_arm__length_0_04_meter_material"/>
        <!-- Link r_hip_inner_passive_link_x -->
        <body name="r_hip_inner_passive_link_x" pos="-0.04 -6.93889e-18 0.004175" quat="0.338623 -0.330409 -0.62315 0.622775">
          <!-- Joint from hip_arm__configuration_default_3 to r_hip_inner_passive_link_x -->
          <joint axis="1 0 0" name="r_hip_inner_passive_x" type="hinge"/>
          <inertial pos="0 0 0" mass="1e-09" fullinertia="1e-09 1e-09 1e-09 0 0 0"/>
          <!-- Link r_hip_inner_passive_link_y -->
          <body name="r_hip_inner_passive_link_y" pos="8.67362e-19 0 0" quat="1 0 8.32667e-17 -2.77556e-17">
            <!-- Joint from r_hip_inner_passive_link_x to r_hip_inner_passive_link_y -->
            <joint axis="0 1 0" name="r_hip_inner_passive_y" type="hinge"/>
            <inertial pos="0 0 0" mass="1e-09" fullinertia="1e-09 1e-09 1e-09 0 0 0"/>
            <!-- Link linkage__43d788dc267bdd7f4fb3b94dc32a7642_3 -->
            <body name="linkage__43d788dc267bdd7f4fb3b94dc32a7642_3" pos="8.67362e-19 0 0" quat="1 0 8.32667e-17 -2.77556e-17">
              <!-- Joint from r_hip_inner_passive_link_y to linkage__43d788dc267bdd7f4fb3b94dc32a7642_3 -->
              <joint axis="0 0 1" name="r_hip_inner_passive_z" type="hinge"/>
              <inertial pos="-0.02625 -1.67941e-08 -2.69255e-17" mass="0.00171492" fullinertia="9.7543e-09 4.50395e-07 4.46417e-07 -5.16338e-23 -2.26912e-12 3.79359e-23"/>
              <!-- Part 59935k13_ball_joint_rod_end_20 -->
              <geom type="mesh" class="visual" pos="-0.0125 0 1.38778e-17" quat="0.5 -0.5 -0.5 -0.5" mesh="59935k13_ball_joint_rod_end__2" material="59935k13_ball_joint_rod_end__2_material"/>
              <geom type="mesh" class="collision" pos="-0.0125 0 1.38778e-17" quat="0.5 -0.5 -0.5 -0.5" mesh="59935k13_ball_joint_rod_end__2" material="59935k13_ball_joint_rod_end__2_material"/>
              <!-- Part part_3__length_0_0525_meter_3 -->
              <geom type="mesh" class="visual" pos="-0.0125 3.46945e-18 -1.38778e-17" quat="0.5 -0.5 -0.5 -0.5" mesh="part_3__length_0_0525_meter" material="part_3__length_0_0525_meter_material"/>
              <geom type="mesh" class="collision" pos="-0.0125 3.46945e-18 -1.38778e-17" quat="0.5 -0.5 -0.5 -0.5" mesh="part_3__length_0_0525_meter" material="part_3__length_0_0525_meter_material"/>
              <!-- Part 59935k13_ball_joint_rod_end_21 -->
              <geom type="mesh" class="visual" pos="-0.04 -3.46945e-18 -6.93889e-17" quat="0.5 -0.5 0.5 0.5" mesh="59935k13_ball_joint_rod_end__2" material="59935k13_ball_joint_rod_end__2_material"/>
              <geom type="mesh" class="collision" pos="-0.04 -3.46945e-18 -6.93889e-17" quat="0.5 -0.5 0.5 0.5" mesh="59935k13_ball_joint_rod_end__2" material="59935k13_ball_joint_rod_end__2_material"/>
              <!-- Frame closing_r_hip_inner_1 -->
              <site group="3" name="closing_r_hip_inner_1" pos="-0.0525 3.46945e-18 -8.32667e-17" quat="2.22045e-16 -7.9841e-17 1 2.77556e-16"/>
            </body>
          </body>
        </body>
      </body>
      <!-- Link hip_arm__configuration_default_4 -->
      <body name="hip_arm__configuration_default_4" pos="-0.09175 -0.01425 -0.0386505" quat="0.641224 0.298046 0.641224 0.298046">
        <!-- Joint from trunk to hip_arm__configuration_default_4 -->
        <joint axis="0 0 1" name="r_hip_outer" type="hinge"/>
        <inertial pos="0.0118225 0.0160747 0.00681107" mass="0.00480721" fullinertia="9.50491e-07 5.47113e-07 1.41312e-06 -6.33349e-07 9.78285e-09 1.24883e-08"/>
        <!-- Part 59935k13_ball_joint_rod_end_22 -->
        <geom type="mesh" class="visual" pos="0.0135827 0.0396454 0.004175" quat="0.451924 -1.91526e-15 2.22045e-16 -0.892057" mesh="59935k13_ball_joint_rod_end" material="59935k13_ball_joint_rod_end_material"/>
        <geom type="mesh" class="collision" pos="0.0135827 0.0396454 0.004175" quat="0.451924 -1.91526e-15 2.22045e-16 -0.892057" mesh="59935k13_ball_joint_rod_end" material="59935k13_ball_joint_rod_end_material"/>
        <!-- Part hip_arm__length_0_04_meter_6 -->
        <geom type="mesh" class="visual" pos="6.93889e-18 -1.38778e-17 -4.16334e-17" quat="0.451924 -2.17014e-16 -7.63278e-17 -0.892057" mesh="hip_arm__length_0_04_meter" material="hip_arm__length_0_04_meter_material"/>
        <geom type="mesh" class="collision" pos="6.93889e-18 -1.38778e-17 -4.16334e-17" quat="0.451924 -2.17014e-16 -7.63278e-17 -0.892057" mesh="hip_arm__length_0_04_meter" material="hip_arm__length_0_04_meter_material"/>
        <!-- Link r_hip_outer_passive_link_x -->
        <body name="r_hip_outer_passive_link_x" pos="0.0236612 0.0322513 0.004175" quat="0.67199 -0.67199 0.220066 -0.220066">
          <!-- Joint from hip_arm__configuration_default_4 to r_hip_outer_passive_link_x -->
          <joint axis="1 0 0" name="r_hip_outer_passive_x" type="hinge"/>
          <inertial pos="0 0 0" mass="1e-09" fullinertia="1e-09 1e-09 1e-09 0 0 0"/>
          <!-- Link r_hip_outer_passive_link_y -->
          <body name="r_hip_outer_passive_link_y" pos="0 -1.38778e-17 3.46945e-18" quat="1 0 -1.53315e-16 7.59843e-18">
            <!-- Joint from r_hip_outer_passive_link_x to r_hip_outer_passive_link_y -->
            <joint axis="0 1 0" name="r_hip_outer_passive_y" type="hinge"/>
            <inertial pos="0 0 0" mass="1e-09" fullinertia="1e-09 1e-09 1e-09 0 0 0"/>
            <!-- Link linkage__43d788dc267bdd7f4fb3b94dc32a7642_4 -->
            <body name="linkage__43d788dc267bdd7f4fb3b94dc32a7642_4" pos="0 -1.38778e-17 3.46945e-18" quat="1 0 -1.53315e-16 7.59843e-18">
              <!-- Joint from r_hip_outer_passive_link_y to linkage__43d788dc267bdd7f4fb3b94dc32a7642_4 -->
              <joint axis="0 0 1" name="r_hip_outer_passive_z" type="hinge"/>
              <inertial pos="0.0259374 0.000187483 -0.00403488" mass="0.00171492" fullinertia="2.00936e-08 4.50364e-07 4.36108e-07 -3.13755e-09 6.63202e-08 3.06663e-10"/>
              <!-- Part 59935k13_ball_joint_rod_end_23 -->
              <geom type="mesh" class="visual" pos="0.0395236 0.000285714 -0.00614839" quat="0.52842 -0.545336 -0.473649 -0.446136" mesh="59935k13_ball_joint_rod_end__2" material="59935k13_ball_joint_rod_end__2_material"/>
              <geom type="mesh" class="collision" pos="0.0395236 0.000285714 -0.00614839" quat="0.52842 -0.545336 -0.473649 -0.446136" mesh="59935k13_ball_joint_rod_end__2" material="59935k13_ball_joint_rod_end__2_material"/>
              <!-- Part part_3__length_0_0525_meter_4 -->
              <geom type="mesh" class="visual" pos="0.0395236 0.000285714 -0.00614839" quat="0.52842 -0.545336 -0.473649 -0.446136" mesh="part_3__length_0_0525_meter" material="part_3__length_0_0525_meter_material"/>
              <geom type="mesh" class="collision" pos="0.0395236 0.000285714 -0.00614839" quat="0.52842 -0.545336 -0.473649 -0.446136" mesh="part_3__length_0_0525_meter" material="part_3__length_0_0525_meter_material"/>
              <!-- Part 59935k13_ball_joint_rod_end_24 -->
              <geom type="mesh" class="visual" pos="0.0123511 8.92857e-05 -0.00192137" quat="0.446136 -0.473649 0.545336 0.52842" mesh="59935k13_ball_joint_rod_end__2" material="59935k13_ball_joint_rod_end__2_material"/>
              <geom type="mesh" class="collision" pos="0.0123511 8.92857e-05 -0.00192137" quat="0.446136 -0.473649 0.545336 0.52842" mesh="59935k13_ball_joint_rod_end__2" material="59935k13_ball_joint_rod_end__2_material"/>
              <!-- Frame closing_r_hip_outer_1 -->
              <site group="3" name="closing_r_hip_outer_1" pos="0.0518747 0.000375 -0.00806977" quat="0.996771 -0.0222146 0.0769858 0.00529875"/>
            </body>
          </body>
        </body>
      </body>
    </body>
  </worldbody>
  <asset>
    <mesh file="59935k13_ball_joint_rod_end.stl"/>
    <mesh file="r_thigh_outer_plate.stl"/>
    <mesh file="r_outer_arm.stl"/>
    <mesh file="upper_carriage__2.stl"/>
    <mesh file="standoff.stl"/>
    <mesh file="59935k13_ball_joint_rod_end__2.stl"/>
    <mesh file="part_3__length_0_12_meter.stl"/>
    <mesh file="l_outer_plate.stl"/>
    <mesh file="r_inner_arm.stl"/>
    <mesh file="l_inner_plate.stl"/>
    <mesh file="lower_carriage.stl"/>
    <mesh file="ankle__2.stl"/>
    <mesh file="m2006_p36_3.stl"/>
    <mesh file="m2006_p36_3__2.stl"/>
    <mesh file="6656k118_ultra_thin_ball_bearing.stl"/>
    <mesh file="upper_carriage.stl"/>
    <mesh file="l_inner_arm.stl"/>
    <mesh file="part_3__length_0_0525_meter.stl"/>
    <mesh file="5972k222_ball_bearing.stl"/>
    <mesh file="l_outer_arm.stl"/>
    <mesh file="hip_arm__length_0_04_meter.stl"/>
    <mesh file="foot.stl"/>
    <mesh file="superstructure.stl"/>
    <mesh file="part_3.stl"/>
    <mesh file="ankle.stl"/>
    <material name="m2006_p36_3_material" rgba="0.917647 0.917647 0.917647 1"/>
    <material name="upper_carriage_material" rgba="0.917647 0.917647 0.917647 1"/>
    <material name="superstructure_material" rgba="0.647059 0.647059 0.647059 1"/>
    <material name="upper_carriage__2_material" rgba="0.917647 0.917647 0.917647 1"/>
    <material name="6656k118_ultra_thin_ball_bearing_material" rgba="0.498039 0.498039 0.498039 1"/>
    <material name="5972k222_ball_bearing_material" rgba="0.972549 0.529412 0.00392157 1"/>
    <material name="lower_carriage_material" rgba="0.917647 0.917647 0.917647 1"/>
    <material name="l_outer_arm_material" rgba="0.498039 0.498039 0.498039 1"/>
    <material name="59935k13_ball_joint_rod_end_material" rgba="0.917647 0.917647 0.917647 1"/>
    <material name="l_inner_plate_material" rgba="0.917647 0.917647 0.917647 1"/>
    <material name="l_inner_arm_material" rgba="0.647059 0.647059 0.647059 1"/>
    <material name="m2006_p36_3__2_material" rgba="0.917647 0.917647 0.917647 1"/>
    <material name="l_outer_plate_material" rgba="0.615686 0.811765 0.929412 1"/>
    <material name="standoff_material" rgba="0.917647 0.917647 0.917647 1"/>
    <material name="ankle_material" rgba="0.615686 0.811765 0.929412 1"/>
    <material name="ankle__2_material" rgba="0.615686 0.811765 0.929412 1"/>
    <material name="part_3_material" rgba="0.647059 0.647059 0.647059 1"/>
    <material name="foot_material" rgba="0.615686 0.811765 0.929412 1"/>
    <material name="hip_arm__length_0_04_meter_material" rgba="0.231373 0.380392 0.705882 1"/>
    <material name="59935k13_ball_joint_rod_end__2_material" rgba="0.768627 0.886275 0.952941 1"/>
    <material name="part_3__length_0_12_meter_material" rgba="0.231373 0.380392 0.705882 1"/>
    <material name="r_thigh_outer_plate_material" rgba="0.615686 0.811765 0.929412 1"/>
    <material name="r_outer_arm_material" rgba="0.498039 0.498039 0.498039 1"/>
    <material name="r_inner_arm_material" rgba="0.647059 0.647059 0.647059 1"/>
    <material name="part_3__length_0_0525_meter_material" rgba="0.231373 0.380392 0.705882 1"/>
  </asset>
  <actuator>
    <position class="C:\Users\steph\code\arca\arca-sim\models\full\mjcf" name="l_knee" joint="l_knee" inheritrange="1"/>
    <position class="C:\Users\steph\code\arca\arca-sim\models\full\mjcf" name="r_knee" joint="r_knee"/>
    <position class="C:\Users\steph\code\arca\arca-sim\models\full\mjcf" name="l_hip_inner" joint="l_hip_inner"/>
    <position class="C:\Users\steph\code\arca\arca-sim\models\full\mjcf" name="l_hip_outer" joint="l_hip_outer"/>
    <position class="C:\Users\steph\code\arca\arca-sim\models\full\mjcf" name="r_hip_inner" joint="r_hip_inner"/>
    <position class="C:\Users\steph\code\arca\arca-sim\models\full\mjcf" name="r_hip_outer" joint="r_hip_outer"/>
  </actuator>
  <equality>
    <connect site1="closing_l_knee_linkage_1" site2="closing_l_knee_linkage_2"/>
    <connect site1="closing_r_knee_1" site2="closing_r_knee_2"/>
    <connect site1="closing_l_hip_inner_1" site2="closing_l_hip_inner_2"/>
    <connect site1="closing_l_hip_outer_1" site2="closing_l_hip_outer_2"/>
    <connect site1="closing_r_hip_outer_1" site2="closing_r_hip_outer_2"/>
    <connect site1="closing_r_hip_inner_1" site2="closing_r_hip_inner_2"/>
  </equality>
</mujoco>
